<?xml version="1.0"?>
<robot name="$(arg prefix)" xmlns:xacro="http://www.ros.org/wiki/xacro">

    <!-- Rigid body description of the base link -->
	<link name="$(arg prefix)">
		<visual>
			<origin xyz="0.2 0 0" rpy="${pi/2} 0 ${pi}"/>
			<geometry>
				<mesh filename="package://riptide_description_sim/meshes/riptide_body.stl" scale="0.001 0.001 0.001"/>
			</geometry>
		  </visual>
	</link>

	<link name="$(arg prefix)_echosounder"/>

	<joint name="$(arg prefix)_echosounder" type="fixed">
		<origin rpy="0 ${pi/2} 0" xyz="0.28 0 -0.05"/>
		<parent link="$(arg prefix)"/>
		<child link="$(arg prefix)_echosounder"/>
	</joint>

	<link name="$(arg prefix)_thruster">
		<visual>
			<origin xyz="0 0 0" rpy="0 0 0" />
			<geometry>
				<mesh filename="package://riptide_description_sim/meshes/propeller.dae" scale="1.5 1.5 1.5"/>
			</geometry>
		</visual>
	</link>

	<joint name="$(arg prefix)_thruster" type="continuous">
		<axis xyz="1 0 0"/>
		<origin rpy="0 0 0" xyz="-0.51 0 0"/>
		<parent link="$(arg prefix)"/>
		<child link="$(arg prefix)_thruster"/>
	</joint>

	<xacro:include filename="$(find riptide_description_sim)/urdf/riptide_fin.urdf.xacro"/>

	<xacro:riptide_fin name="d" orientation="0"/>
	<xacro:riptide_fin name="p" orientation="1"/>
	<xacro:riptide_fin name="s" orientation="2"/>

    <!-- ROS2 control hardware interfaces -->
    <xacro:include filename="riptide_imu.urdf.xacro"/>
	<xacro:include filename="riptide_actuators.urdf.xacro"/>
	<xacro:include filename="riptide_echosounder.urdf.xacro"/>
	<xacro:include filename="riptide_pressure.urdf.xacro"/>
	<xacro:include filename="riptide_battery.urdf.xacro"/>
    
</robot>